Workbook

Sheet Soal
A2: TECHNICAL TEST DATA ANALYST | C2: Rubrik Penilaian
C3: Komponen | D3: Bobot (%) | E3: Kriteria Penilaian
A4: Durasi pengerjaan: 96 Jam | C4: Data Handling | D4: 25 | E4: Menghapus error, memperbaiki missing, validasi perhitungan jam kerja
A5: Simpan hasil Technical Test dengan bentuk file Excel lalu kirim melalui Whatsapp. | C5: Excel Formula | D5: 20 | E5: Ketepatan rumus, penggunaan XLOOKUP, IF, SUMIFS
C6: Pivot Table | D6: 20 | E6: Struktur benar, perhitungan akurat, filter berfungsi
A7: A. Data Handling | C7: Dashboard | D7: 25 | E7: Clean, insightful, layout rapih, grafik relevan
A8: 1. Identifikasi dan perbaiki format tanggal (misal: 2024/13/40). Normalisasi seluruh tanggal menjadi format YYYY-MM-DD. | C8: Analytical Insight | D8: 10 | E8: Logis, berbasis data, tidak terlalu umum
A9: 2. Temukan dan tangani missing values pada seluruh kolom Produksi dan Hauling, jelaskan metode penanganan yang digunakan.
A10: 3. Validasi dan koreksi nilai Shift yang salah menjadi kategori yang benar (Day/Night). | C10: Link Dashboard | D10: Python
A11: 4. Deteksi dan tangani data duplikat pada kedua sheet, jelaskan kriteria duplikasi yang digunakan.
A12: 5. Pastikan seluruh kolom numerik berada dalam format angka, perbaiki baris yang berubah menjadi teks.
A13: 6. Identifikasi konsistensi Working_Hours, Delay_Hours, dan Productive_Hours.
C14: Mohon kerjakan dengan jujur dan teliti, gunakan kesempatan ini sebaik dan semaksimal mungkin. SEMANGAT!!
A15: B. Excel Formula
A16: 1. Hitung Produktivitas Excavator = Coal Volume / Working Hours.
A17: 2. Hitung Fuel Ratio = Fuel Usage / Ritase.
A18: 3. Tandai Cycle Time Abnormal (>10 menit).
A19: 4. Hitung Estimated Fuel = Fuel Rate * Working Hours. (Gunakan XLOOKUP untuk menarik Fuel Rate dari data Fleet Master)
A20: 5. Validasi nilai Working Hours = Productive Hours + Delay Hours.
A21: 6. Identifikasi nilai dari rumus Rasio Stripping = OB_Volume/Coal_Volume, serta hitung rata-rata nya. Contoh: jika mendapat hasil maka 2.5 BCM (OB) perlu dipindahkan untuk mendapat 1 Ton Batu Bara.
A24: C. Pivot Table
A25: 1. Total OB & Coal masing-masing Pit.
A26: 2. Ritase dari unit Dump Truck.
A27: 3. Fuel Usage dari unit Dump Truck.
A28: 4. Rata-rata Cycle Time dari unit Dump Truck.
... A37: Tulis insight ringkas (5–8 kalimat) dari dashboard.
E38: Data Analyst - PT MEGA GLOBAL ENERGY

Sheet Produksi
A1: Tanggal | B1: Pit | C1: Seam | D1: Excavator | E1: Shift | F1: OB_Volume | G1: Coal_Volume | H1: Working_Hours | I1: Delay_Hours | J1: Productive_Hours | K1: Deteksi_Tanggal
A2: 2024-01-01 | B2: Pit C | C2: Seam 1 | D2: EX1100 | E2: Evening | F2: 713 | G2: 6438 | H2: 9.92 | I2: 1.86 | J2: 8.06 | K2: =IF(ISNUMBER(DATEVALUE(A2)),"VALID","INVALID") -> VALID
A3: 2024-01-01 | B3: Pit C | C3: Seam 1 | D3: EX1100 | E3: Night | F3: 713 | G3: 6438 | H3: 9.92 | I3: 1.86 | J3: 8.06 | K3: =IF(ISNUMBER(DATEVALUE(A3)),"VALID","INVALID") -> VALID
A4: 2024-01-01 | B4: Pit C | C4: Seam 2 | D4: EX1100 | E4: Night | F4: 1366 | G4: 1078 | H4: 4.44 | I4: 0.72 | J4: 3.72 | K4: =IF(ISNUMBER(DATEVALUE(A4)),"VALID","INVALID") -> VALID
A5: 2024-01-01 | B5: Pit C | C5: Seam 1 | D5: EX1100 | E5: Evening | G5: 6438 | H5: 9.92 | I5: 1.86 | J5: 8.06 | K5: =IF(ISNUMBER(DATEVALUE(A5)),"VALID","INVALID") -> VALID
A6: 2024-01-01 | B6: Pit C | C6: Seam 1 | D6: EX1100 | E6: Night | F6: 713 | G6: 6438 | H6: 9.92 | I6: 1.86 | J6: 8.06 | K6: =IF(ISNUMBER(DATEVALUE(A6)),"VALID","INVALID") -> VALID
A7: 2024-01-01 | B7: Pit C | C7: Seam 2 | D7: EX1100 | E7: Night | F7: 1366 | G7: 1078 | H7: 4.44 | I7: 0.72 | J7: 3.72 | K7: =IF(ISNUMBER(DATEVALUE(A7)),"VALID","INVALID") -> VALID
A8: 2024-01-01 | B8: Pit C | C8: Seam 1 | D8: EX1100 | E8: Night | F8: 713 | G8: 6438 | H8: 9.92 | I8: 1.86 | J8: 8.06 | K8: =IF(ISNUMBER(DATEVALUE(A8)),"VALID","INVALID") -> VALID
A9: 2024-01-02 | B9: Pit A | C9: Seam 1 | D9: EX2500 | E9: Day | F9: 2612 | G9: 2675 | H9: 7.16 | I9: 1.5 | J9: 5.66 | K9: =IF(ISNUMBER(DATEVALUE(A9)),"VALID","INVALID") -> VALID
A10: 2024-01-02 | B10: Pit A | C10: Seam 1 | D10: EX2500 | E10: Day | F10: 2612 | G10: 2675 | H10: 7.16 | I10: 1.5 | J10: 5.66 | K10: =IF(ISNUMBER(DATEVALUE(A10)),"VALID","INVALID") -> VALID
A11: 2024-01-02 | B11: Pit B | C11: Seam 2 | D11: EX2500 | E11: Day | F11: 3737 | G11: 269 | H11: 9.95 | I11: 0.78 | J11: 9.17 | K11: =IF(ISNUMBER(DATEVALUE(A11)),"VALID","INVALID") -> VALID
A12: 2024-01-02 | B12: Pit C | C12: Seam 2 | D12: EX2500 | E12: Day | F12: 7669 | G12: 4949 | H12: 7.54 | I12: 0.96 | J12: 6.58 | K12: =IF(ISNUMBER(DATEVALUE(A12)),"VALID","INVALID") -> VALID
A13: 2024-01-02 | B13: Pit B | C13: Seam 2 | D13: EX2500 | E13: Evening | F13: 3737 | G13: 269 | H13: 9.95 | I13: 0.78 | J13: 9.17 | K13: =IF(ISNUMBER(DATEVALUE(A13)),"VALID","INVALID") -> VALID
A14: 2024-01-03 | B14: Pit A | C14: Seam 2 | D14: EX1200 | E14: Night | F14: 2604 | G14: 1318 | H14: 6.25 | I14: 1.14 | J14: 5.11 | K14: =IF(ISNUMBER(DATEVALUE(A14)),"VALID","INVALID") -> VALID
A15: 2024-01-03 | B15: Pit A | C15: Seam 1 | D15: EX1200 | E15: Night | F15: 684 | G15: 1349 | H15: 5.43 | I15: 0.27 | J15: 5.16 | K15: =IF(ISNUMBER(DATEVALUE(A15)),"VALID","INVALID") -> VALID
A16: 2024-01-03 | B16: Pit A | C16: Seam 2 | D16: EX1200 | E16: Day | F16: 8978 | G16: 3637 | H16: 4.71 | I16: 0.08 | J16: 4.63 | K16: =IF(ISNUMBER(DATEVALUE(A16)),"VALID","INVALID") -> VALID
A17: 2024-01-03 | B17: Pit A | C17: Seam 1 | D17: EX1100 | E17: Evening | F17: 3336 | G17: 2526 | H17: 6.14 | I17: 0.63 | J17: 5.51 | K17: =IF(ISNUMBER(DATEVALUE(A17)),"VALID","INVALID") -> VALID
... A25: 2024-01-03 | B25: Pit A | C25: Seam 2 | D25: EX1200 | E25: Day | F25: 8978 | G25: 3637 | H25: 4.71 | I25: 0.08 | J25: 4.63 | K25: =IF(ISNUMBER(DATEVALUE(A25)),"VALID","INVALID") -> VALID
A26: 2024-01-03 | B26: Pit A | C26: Seam 2 | D26: EX1200 | E26: Day | F26: 8978 | H26: 4.71 | I26: 0.08 | J26: 4.63 | K26: =IF(ISNUMBER(DATEVALUE(A26)),"VALID","INVALID") -> VALID
A27: 2024-01-03 | B27: Pit B | C27: Seam 2 | D27: EX2500 | E27: Night | F27: 3710 | G27: 3388 | H27: 8.73 | I27: 1.18 | J27: 7.55 | K27: =IF(ISNUMBER(DATEVALUE(A27)),"VALID","INVALID") -> VALID
A28: 2024-01-04 | B28: Pit C | C28: Seam 3 | D28: EX1200 | E28: Evening | F28: 5683 | G28: 5055 | H28: 4.59 | I28: 0.17 | J28: 4.42 | K28: =IF(ISNUMBER(DATEVALUE(A28)),"VALID","INVALID") -> VALID
A29: 2024-01-05 | B29: Pit B | C29: Seam 1 | D29: EX2500 | E29: Night | F29: 4512 | G29: 1543 | H29: 5.16 | I29: 0.03 | J29: 5.13 | K29: =IF(ISNUMBER(DATEVALUE(A29)),"VALID","INVALID") -> VALID
A30: 2024-01-07 | B30: Pit C | C30: Seam 2 | D30: EX1200 | E30: Day | F30: 8608 | G30: 1381 | H30: 5.24 | I30: 0.17 | J30: 5.07 | K30: =IF(ISNUMBER(DATEVALUE(A30)),"VALID","INVALID") -> VALID
A31: 2024-01-07 | B31: Pit A | C31: Seam 1 | D31: EX1200 | E31: Night | F31: 2268 | G31: 5211 | H31: 9.78 | I31: 0.33 | J31: 9.45 | K31: =IF(ISNUMBER(DATEVALUE(A31)),"VALID","INVALID") -> VALID
A32: 2024-01-07 | B32: Pit C | C32: Seam 2 | D32: EX1200 | E32: Day | F32: 8608 | G32: 1381 | H32: 5.24 | I32: 0.17 | J32: 5.07 | K32: =IF(ISNUMBER(DATEVALUE(A32)),"VALID","INVALID") -> VALID
A33: 2024-01-09 | B33: Pit C | C33: Seam 3 | D33: EX1100 | E33: Day | F33: 3338 | G33: 3878 | H33: 9.27 | I33: 0.35 | J33: 8.92 | K33: =IF(ISNUMBER(DATEVALUE(A33)),"VALID","INVALID") -> VALID
A34: 2024-01-09 | B34: Pit B | C34: Seam 1 | D34: EX1200 | E34: Day | F34: 5401 | G34: 78 | H34: 8.17 | I34: 0.51 | J34: 7.66 | K34: =IF(ISNUMBER(DATEVALUE(A34)),"VALID","INVALID") -> VALID
A35: 2024-01-09 | B35: Pit A | C35: Seam 3 | D35: EX1200 | E35: Night | F35: 938 | G35: 2671 | H35: 6.8 | I35: 0.97 | J35: 5.83 | K35: =IF(ISNUMBER(DATEVALUE(A35)),"VALID","INVALID") -> VALID
A36: 2024-01-09 | B36: Pit C | C36: Seam 3 | D36: EX1100 | E36: Day | F36: 3338 | G36: 3878 | H36: 9.27 | I36: 0.35 | J36: 8.92 | K36: =IF(ISNUMBER(DATEVALUE(A36)),"VALID","INVALID") -> VALID
A37: 2024-01-09 | B37: Pit A | C37: Seam 3 | D37: EX1200 | E37: Night | F37: 938 | G37: 2671 | H37: 6.8 | I37: 0.97 | J37: 5.83 | K37: =IF(ISNUMBER(DATEVALUE(A37)),"VALID","INVALID") -> VALID
A38: 2024-01-09 | B38: Pit C | C38: Seam 3 | D38: EX1100 | E38: Day | F38: 3338 | G38: 3878 | H38: 9.27 | I38: 0.35 | J38: 8.92 | K38: =IF(ISNUMBER(DATEVALUE(A38)),"VALID","INVALID") -> VALID
... A50: 2024-01-14 | B50: Pit A | C50: Seam 1 | D50: EX2500 | E50: Day | F50: 6140 | G50: 68 | H50: 5.95 | I50: 0.06 | J50: 5.89 | K50: =IF(ISNUMBER(DATEVALUE(A50)),"VALID","INVALID") -> VALID
A51: 2024-01-14 | B51: Pit C | C51: Seam 1 | D51: EX1100 | E51: Night | F51: 8322 | H51: 9.36 | I51: 1.99 | J51: 7.37 | K51: =IF(ISNUMBER(DATEVALUE(A51)),"VALID","INVALID") -> VALID
A52: 2024-01-14 | B52: Pit A | C52: Seam 1 | D52: EX2500 | E52: Day | F52: 6140 | G52: 68 | H52: 5.95 | I52: 0.06 | J52: 5.89 | K52: =IF(ISNUMBER(DATEVALUE(A52)),"VALID","INVALID") -> VALID
A53: 2024-01-14 | B53: Pit C | C53: Seam 1 | D53: EX1100 | E53: Night | F53: 8322 | G53: 5039 | H53: 9.36 | I53: 1.99 | J53: 7.37 | K53: =IF(ISNUMBER(DATEVALUE(A53)),"VALID","INVALID") -> VALID
A54: 2024-01-14 | B54: Pit A | C54: Seam 3 | D54: EX2500 | E54: Day | F54: 5415 | G54: 5800 | H54: 4.57 | I54: 0.38 | J54: 4.19 | K54: =IF(ISNUMBER(DATEVALUE(A54)),"VALID","INVALID") -> VALID
A55: 2024-01-14 | B55: Pit A | C55: Seam 3 | D55: EX2500 | E55: Day | F55: 5415 | G55: 5800 | H55: 4.57 | I55: 0.38 | J55: 4.19 | K55: =IF(ISNUMBER(DATEVALUE(A55)),"VALID","INVALID") -> VALID
A56: 2024-01-14 | B56: Pit A | C56: Seam 3 | D56: EX2500 | E56: Day | F56: 5415 | G56: 5800 | H56: 4.57 | I56: 0.38 | J56: 4.19 | K56: =IF(ISNUMBER(DATEVALUE(A56)),"VALID","INVALID") -> VALID
A57: 2024-01-15 | B57: Pit A | C57: Seam 1 | D57: EX1100 | E57: Day | F57: 7864 | G57: 4876 | H57: 6.23 | I57: 1.01 | J57: 5.22 | K57: =IF(ISNUMBER(DATEVALUE(A57)),"VALID","INVALID") -> VALID
A58: 2024-01-15 | B58: Pit A | C58: Seam 1 | D58: EX1200 | E58: Day | F58: 4629 | G58: 6379 | H58: 6.26 | I58: 1.64 | J58: 4.62 | K58: =IF(ISNUMBER(DATEVALUE(A58)),"VALID","INVALID") -> VALID
...

Sheet Hauling
A1: Tanggal | B1: Dump_Truck | C1: Distance_km | D1: Cycle_Time_min | E1: Ritase | F1: Fuel_Usage_L | G1: Deteksi_Tanggal
A2: 2024-01-01 | B2: DT03 | C2: 3.85 | D2: 8.63 | E2: 27 | F2: 85.69 | G2: =IF(ISNUMBER(DATEVALUE(A2)),"VALID","INVALID") -> VALID
A3: 2024-01-03 | B3: DT03 | C3: 3.86 | D3: 9.33 | E3: 43 | F3: 135.67 | G3: =IF(ISNUMBER(DATEVALUE(A3)),"VALID","INVALID") -> VALID
A4: 2024-01-03 | B4: DT03 | C4: 3.86 | D4: 9.33 | E4: 43 | F4: 135.67 | G4: =IF(ISNUMBER(DATEVALUE(A4)),"VALID","INVALID") -> VALID
A5: 2024-01-03 | B5: DT01 | C5: 6.1 | D5: 11.43 | E5: 20 | F5: 50.09 | G5: =IF(ISNUMBER(DATEVALUE(A5)),"VALID","INVALID") -> VALID
A6: 2024-01-04 | B6: DT02 | C6: 4.94 | D6: 8.73 | E6: 42 | F6: 118.19 | G6: =IF(ISNUMBER(DATEVALUE(A6)),"VALID","INVALID") -> VALID
A7: 2024-01-04 | B7: DT02 | C7: 4.94 | D7: 8.73 | E7: 42 | F7: 118.19 | G7: =IF(ISNUMBER(DATEVALUE(A7)),"VALID","INVALID") -> VALID
A8: 2024-01-04 | B8: DT05 | C8: 4.08 | D8: 5.88 | E8: 32 | F8: 103.67 | G8: =IF(ISNUMBER(DATEVALUE(A8)),"VALID","INVALID") -> VALID
A9: 2024-01-07 | B9: DT05 | C9: 3.52 | D9: 8.71 | E9: 20 | F9: 66.83 | G9: =IF(ISNUMBER(DATEVALUE(A9)),"VALID","INVALID") -> VALID
A10: 2024-01-07 | B10: DT02 | C10: 5.93 | D10: 9.03 | E10: 16 | F10: 32.38 | G10: =IF(ISNUMBER(DATEVALUE(A10)),"VALID","INVALID") -> VALID
A11: 2024-01-07 | B11: DT04 | C11: 5.11 | D11: 8.66 | E11: 45 | F11: 135.11 | G11: =IF(ISNUMBER(DATEVALUE(A11)),"VALID","INVALID") -> VALID
A12: 2024-01-07 | B12: DT02 | C12: 3.34 | D12: 13.06 | E12: 27 | F12: 69.2 | G12: =IF(ISNUMBER(DATEVALUE(A12)),"VALID","INVALID") -> VALID
A13: 2024-01-07 | B13: DT02 | C13: 7.98 | D13: 9.53 | E13: 32 | F13: 73.96 | G13: =IF(ISNUMBER(DATEVALUE(A13)),"VALID","INVALID") -> VALID
... A28: 2024-01-10 | B28: DT03 | C28: 4.68 | D28: 8.76 | E28: 25 | F28: 59.96 | G28: =IF(ISNUMBER(DATEVALUE(A28)),"VALID","INVALID") -> VALID
A29: 2024-01-10 | B29: DT03 | C29: 4.68 | D29: 8.76 | E29: 25 | G29: =IF(ISNUMBER(DATEVALUE(A29)),"VALID","INVALID") -> VALID
A30: 2024-01-10 | B30: DT04 | C30: 5.32 | D30: 7.89 | E30: 35 | F30: 118.77 | G30: =IF(ISNUMBER(DATEVALUE(A30)),"VALID","INVALID") -> VALID
A31: 2024-01-10 | B31: DT03 | C31: 4.68 | D31: 8.76 | E31: 25 | F31: 59.96 | G31: =IF(ISNUMBER(DATEVALUE(A31)),"VALID","INVALID") -> VALID
A32: 2024-01-10 | B32: DT03 | C32: 4.68 | D32: 8.76 | E32: 25 | F32: 59.96 | G32: =IF(ISNUMBER(DATEVALUE(A32)),"VALID","INVALID") -> VALID
A33: 2024-01-10 | B33: DT03 | C33: 6.61 | D33: 12.22 | E33: 39 | F33: 78.21 | G33: =IF(ISNUMBER(DATEVALUE(A33)),"VALID","INVALID") -> VALID
A34: 2024-01-10 | B34: DT04 | C34: 5.32 | D34: 7.89 | E34: 35 | F34: 118.77 | G34: =IF(ISNUMBER(DATEVALUE(A34)),"VALID","INVALID") -> VALID
A35: 2024-01-11 | B35: DT01 | C35: 4.05 | D35: 9.03 | E35: 16 | F35: 32.62 | G35: =IF(ISNUMBER(DATEVALUE(A35)),"VALID","INVALID") -> VALID
A36: 2024-01-11 | B36: DT01 | C36: 4.05 | D36: 9.03 | E36: 16 | F36: 32.62 | G36: =IF(ISNUMBER(DATEVALUE(A36)),"VALID","INVALID") -> VALID
A37: 2024-01-12 | B37: DT01 | C37: 6.56 | D37: 7.02 | E37: 35 | F37: 71.32 | G37: =IF(ISNUMBER(DATEVALUE(A37)),"VALID","INVALID") -> VALID
A38: 2024-01-12 | B38: DT01 | C38: 7.97 | D38: 7.7 | E38: 18 | F38: 56.19 | G38: =IF(ISNUMBER(DATEVALUE(A38)),"VALID","INVALID") -> VALID
A39: 2024-01-12 | B39: DT05 | C39: 4.04 | D39: 5.52 | E39: 30 | F39: 78.6 | G39: =IF(ISNUMBER(DATEVALUE(A39)),"VALID","INVALID") -> VALID
A40: 2024-01-12 | B40: DT03 | C40: 6.61 | D40: 12.47 | E40: 41 | F40: 137.43 | G40: =IF(ISNUMBER(DATEVALUE(A40)),"VALID","INVALID") -> VALID
A41: 2024-01-14 | B41: DT02 | C41: 6.63 | D41: 7.09 | E41: 18 | F41: 55.57 | G41: =IF(ISNUMBER(DATEVALUE(A41)),"VALID","INVALID") -> VALID
... A52: 2024-01-17 | B52: DT04 | C52: 5.02 | D52: 6.06 | E52: 43 | F52: 119.57 | G52: =IF(ISNUMBER(DATEVALUE(A52)),"VALID","INVALID") -> VALID
A53: 2024-01-17 | B53: DT04 | C53: 7.85 | D53: 9.75 | E53: 36 | G53: =IF(ISNUMBER(DATEVALUE(A53)),"VALID","INVALID") -> VALID
A54: 2024-01-17 | B54: DT02 | C54: 4.36 | D54: 11.31 | E54: 29 | F54: 56.56 | G54: =IF(ISNUMBER(DATEVALUE(A54)),"VALID","INVALID") -> VALID
A55: 2024-01-17 | B55: DT04 | C55: 7.85 | D55: 9.75 | E55: 36 | F55: 81.66 | G55: =IF(ISNUMBER(DATEVALUE(A55)),"VALID","INVALID") -> VALID
A56: 2024-01-17 | B56: DT04 | C56: 5.02 | D56: 6.06 | E56: 43 | F56: 119.57 | G56: =IF(ISNUMBER(DATEVALUE(A56)),"VALID","INVALID") -> VALID
A57: 2024-01-17 | B57: DT04 | C57: 7.85 | D57: 9.75 | E57: 36 | F57: 81.66 | G57: =IF(ISNUMBER(DATEVALUE(A57)),"VALID","INVALID") -> VALID
A58: 2024-01-18 | B58: DT04 | C58: 2.96 | D58: 6.6 | E58: 30 | F58: 73.32 | G58: =IF(ISNUMBER(DATEVALUE(A58)),"VALID","INVALID") -> VALID
A59: 2024-01-18 | B59: DT04 | C59: 2.96 | D59: 6.6 | E59: 30 | F59: 73.32 | G59: =IF(ISNUMBER(DATEVALUE(A59)),"VALID","INVALID") -> VALID
A60: 2024-01-18 | B60: DT04 | C60: 2.96 | D60: 6.6 | E60: 30 | F60: 73.32 | G60: =IF(ISNUMBER(DATEVALUE(A60)),"VALID","INVALID") -> VALID
A61: 2024-01-18 | B61: DT04 | C61: 2.96 | D61: 6.6 | E61: 30 | F61: 73.32 | G61: =IF(ISNUMBER(DATEVALUE(A61)),"VALID","INVALID") -> VALID
A62: 2024-01-18 | B62: DT04 | C62: 2.96 | D62: 6.6 | E62: 30 | F62: 73.32 | G62: =IF(ISNUMBER(DATEVALUE(A62)),"VALID","INVALID") -> VALID
A63: 2024-01-18 | B63: DT04 | C63: 2.96 | D63: 6.6 | E63: 30 | F63: 73.32 | G63: =IF(ISNUMBER(DATEVALUE(A63)),"VALID","INVALID") -> VALID
A64: 2024-01-18 | B64: DT04 | C64: 2.96 | D64: 6.6 | E64: 30 | F64: 73.32 | G64: =IF(ISNUMBER(DATEVALUE(A64)),"VALID","INVALID") -> VALID
...

Sheet Fleet Master
A1: Unit | B1: Type | C1: Capacity | D1: Fuel_Rate_L_per_Hour
A2: EX1100 | B2: Excavator | C2: 7 | D2: 45
A3: EX1200 | B3: Excavator | C3: 8 | D3: 48
A4: EX2500 | B4: Excavator | C4: 15 | D4: 75
A5: DT01 | B5: Dump Truck | C5: 35 | D5: 22
A6: DT02 | B6: Dump Truck | C6: 35 | D6: 22
A7: DT03 | B7: Dump Truck | C7: 40 | D7: 25
A8: DT04 | B8: Dump Truck | C8: 40 | D8: 25
A9: DT05 | B9: Dump Truck | C9: 45 | D9: 30

Sheet Technical Test
A1: TECHNICAL TEST DATA ANALYST
A3: A. Data Handling
A4: 1. | B4: Identifikasi dan perbaiki format tanggal (misal: 2024/13/40). Normalisasi seluruh tanggal menjadi format YYYY-MM-DD.
B5: a. | C5: Identifikasi dengan cara menambah kolom "Deteksi_Tanggal" pada sheet "Produksi" untuk mengidentifikasi tanggal "Valid" atau "Invalid". Tanggal invalid ditandai dengan warna kuning.
B6: b. | C6: Membuat sheet baru "Produksi_Filled" sebagai sheet untuk proses cleaning data "Produksi". Kolom "Tanggal" diubah format menjadi date.
B7: c. | C7: Menambahkan kolom "Normalisasi_Tanggal" untuk memperbaiki tanggal tidak valid dengan mencocokkan pola data yang identik dari tanggal yang valid.
B8: d. | C8: Jika tidak ditemukan tanggal valid, maka digunakan pendekatan berdasarkan kombinasi Pit, Seam, Excavator, dan Shift yang sama. Apabila terdapat beberapa tanggal valid, maka digunakan nilai median sebagai representasi tanggal pengganti, karena kombinasi tersebut biasanya mencerminkan aktivitas dalam satu area kerja yang berkesinambungan. Dilakukan increase short pada kolom "Normalisasi_Tanggal".
B9: e. | C9: Poin a-c juga dilakukan pada data Hauling, namun untuk poin d menggunakan median berdasarkan pendekatan kombinasi jenis Dump_Truck.
A11: 2. | B11: Temukan dan tangani missing values pada seluruh kolom Produksi dan Hauling, jelaskan metode penanganan yang digunakan.
B12: a. | C12: Pada data "Produksi_Filled", untuk missing value kolom "Tanggal" menggunakan nilai yang identik dengan pola tersebut. Missing value pada kolom Pit, Seam, dan Excavator juga menggunakan nilai yang identik dengan pola tersebut. Sedangkan untuk missing value pada kolom OB_Volume, Coal_Volume, dan Delay Hour menggunakan pendekatan nilai identik dan median.
B13: b. | C13: Pada data "Hauling_Filled", untuk missing volue kolom "Dump_Truck" menggunakan pendekatan modus pada tanggal terkait. Missing value pada kolom "Distance_km" menggunakan pendekatan Median berdasarkan kelompok "Dump_Truck". Missing value pada kolom "Cycle_Time_min" dan "Fuel_Usage_L" menggunakan pendekatan berdasarkan kmbinasi kolom lain yang identik dengan data lainnya.
A15: 3. | B15: Validasi dan koreksi nilai Shift yang salah menjadi kategori yang benar (Day/Night).
B16: a. | C16: Pendekatan ini mengandalkan konsistensi pola data historis untuk mengoreksi nilai yang ambigu.
B17: b. | C17: Jika tidak ditemukan baris yang cocok, maka nilai default "Night" digunakan sebagai asumsi konservatif.
A19: 4. | B19: Deteksi dan tangani data duplikat pada kedua sheet, jelaskan kriteria duplikasi yang digunakan.
B20: a. | C20: Hasil penaganan duplikat data "Produksi" terdapat pada sheet "Produksi_Unik", sedangkan untuk data "Hauling" terdapat pada "Hauling_Unik.
B21: b. | C21: Data duplikasi merupakan data yang memiliki karakteristik atau nilai yang sama untuk masing-masing kolom dalam tanggal yang sama.
B22: c. | C22: Data duplikasi ditangani dengan cara di-drop karena bisa menyebabkan bias.
A24: 5. | B24: Pastikan seluruh kolom numerik berada dalam format angka, perbaiki baris yang berubah menjadi teks.
B25: a. | C25: Kolom numerik diganti format datanya menjadi number.
A27: 6. | B27: Identifikasi konsistensi Working_Hours, Delay_Hours, dan Productive_Hours.
B28: a. | C28: Ketiga variabel sudah konsisten, karena "Delay_Hours" diperoleh dari rumus "Working_Hours - Productivity Hours" dan identifikasinya seperti pada kolo "Delay_Cek".
A31: B. Excel Formula
A32: 1. | B32: Hitung Produktivitas Excavator = Coal Volume / Working Hours.
B33: a. | C33: Hasil perhitungan Productivitas Excavator terdapat pada sheet "Produksi_Unik" kolom "Productivitas_Excavator".
A35: 2. | B35: Hitung Fuel Ratio = Fuel Usage / Ritase.
B36: a. | C36: Hasil perhitungan Fuel Ratio terdapat pada sheet "Hauling_Unik" kolom "Fuel_Ratio".
A38: 3. | B38: Tandai Cycle Time Abnormal (>10 menit).
B39: a. | C39: Hasil identifikasi Cycle Time terdapay pada sheet "Hauling_Unik" kolom "Cycle_Time_Cat"
B40: b. | C40: Dari 149 data unik (non duplicate), terdapat 71 data yang termasuk kategori abnormal.
B41: c. | C41: Cycle Time yang lebih lama berarti dalam satu siklus angkut membutuhkan waktu lebih banyak, sehingga jumlah ritase per shigt/hari akan turun.
B42: d. | C42: Jika Fuel Ratio naik saat Cycle Time abnormal, maka konsumsi bahan bakar per ritasi lebih boros.
A44: 4. | B44: Hitung Estimated Fuel = Fuel Rate * Working Hours. (Gunakan XLOOKUP untuk menarik Fuel Rate dari data Fleet Master)
B45: a. | C45: Hasil perhitungan Estimated Fuel terdapat pada sheet "Produksi_Unik" kolom "Estimated_Fuel ".
A47: 5. | B47: Validasi nilai Working Hours = Productive Hours + Delay Hours.
B48: a. | C48: Hasil validasi Working Hours keseluruhannya valid, seperti pada sheet "Produksi_Unik" kolom "Working_Hours_Cek ".
A50: 6. | B50: Identifikasi nilai dari rumus Rasio Stripping = OB_Volume/Coal_Volume, serta hitung rata-rata nya.
B51: Contoh: jika mendapat hasil maka 2.5 BCM (OB) perlu dipindahkan untuk mendapat 1 Ton Batu Bara.
B52: a. | C52: Setelah dihitung menggunakan rumus tersebut dan di rata-rata, bahwa nilai Rasio Stripping sebesar 4.19 maka OB perlu dipindahkan untuk mendapat 1 ton batu bara.
C53: =AVERAGE(Produksi_Unik!Q2:Q150) -> 4.1911055 | D53: =IF(AVERAGE(Produksi_Unik!Q2:Q150)>2.5,"Perlu dipindahkan","Tidak perlu dipindahkan") -> Perlu dipindahkan
...

Sheet Produksi_Filled
A1: Tanggal | B1: Pit | C1: Seam | D1: Excavator | E1: Shift | F1: OB_Volume | G1: Coal_Volume | H1: Working_Hours | I1: Delay_Hours | J1: Productive_Hours | K1: Normalisasi_Tanggal | L1: Validasi_Shift
A2: 2024-01-01 | B2: Pit C | C2: Seam 1 | D2: EX1100 | E2: Evening | F2: 713 | G2: 6438 | H2: 9.92 | I2: 1.86 | J2: 8.06 | K2: {=IF( ISNUMBER(DATEVALUE(A2)), TEXT(DATEVALUE(A2),"yyyy-mm-dd"), IFERROR( TEXT(INDEX($A$2:$A$301,MATCH(1, ($B$2:$B$301=B2) * ($C$2:$C$301=C2) * ($D$2:$D$301=D2) * ($E$2:$E$301=E2) * ($F$2:$F$301=F2) * ($G$2:$G$301=G2) * ($H$2:$H$301=H2) * ($I$2:$I$301=I2) * ($J$2:$J$301=J2),0)),"yyyy-mm-dd"), "Perlu Klarifikasi" ) )} -> 2024-01-01 | L2: {=IF( E2<>"Evening", E2, IFERROR( INDEX($E$2:$E$301, SMALL( IF( ($B$2:$B$301=B2) * ($C$2:$C$301=C2) * ($D$2:$D$301=D2) * ($F$2:$F$301=F2) * ($G$2:$G$301=G2) * ($H$2:$H$301=H2) * ($I$2:$I$301=I2) * ($J$2:$J$301=J2) * ($K$2:$K$301=K2) * ($E$2:$E$301<>"Evening"), ROW($E$2:$E$301)-ROW($E$2)+1, "" ), 1)), "Night" ) )} -> Night
A3: 2024-01-01 | B3: Pit C | C3: Seam 1 | D3: EX1100 | E3: Night | F3: 713 | G3: 6438 | H3: 9.92 | I3: 1.86 | J3: 8.06 | K3: {=IF( ISNUMBER(DATEVALUE(A3)), TEXT(DATEVALUE(A3),"yyyy-mm-dd"), IFERROR( TEXT(INDEX($A$2:$A$301,MATCH(1, ($B$2:$B$301=B3) * ($C$2:$C$301=C3) * ($D$2:$D$301=D3) * ($E$2:$E$301=E3) * ($F$2:$F$301=F3) * ($G$2:$G$301=G3) * ($H$2:$H$301=H3) * ($I$2:$I$301=I3) * ($J$2:$J$301=J3),0)),"yyyy-mm-dd"), "Perlu Klarifikasi" ) )} -> 2024-01-01 | L3: {=IF( E3<>"Evening", E3, IFERROR( INDEX($E$2:$E$301, SMALL( IF( ($B$2:$B$301=B3) * ($C$2:$C$301=C3) * ($D$2:$D$301=D3) * ($F$2:$F$301=F3) * ($G$2:$G$301=G3) * ($H$2:$H$301=H3) * ($I$2:$I$301=I3) * ($J$2:$J$301=J3) * ($K$2:$K$301=K3) * ($E$2:$E$301<>"Evening"), ROW($E$2:$E$301)-ROW($E$2)+1, "" ), 1)), "Night" ) )} -> Night
A4: 2024-01-01 | B4: Pit C | C4: Seam 2 | D4: EX1100 | E4: Night | F4: 1366 | G4: 1078 | H4: 4.44 | I4: 0.72 | J4: 3.72 | K4: {=IF( ISNUMBER(DATEVALUE(A4)), TEXT(DATEVALUE(A4),"yyyy-mm-dd"), IFERROR( TEXT(INDEX($A$2:$A$301,MATCH(1, ($B$2:$B$301=B4) * ($C$2:$C$301=C4) * ($D$2:$D$301=D4) * ($E$2:$E$301=E4) * ($F$2:$F$301=F4) * ($G$2:$G$301=G4) * ($H$2:$H$301=H4) * ($I$2:$I$301=I4) * ($J$2:$J$301=J4),0)),"yyyy-mm-dd"), "Perlu Klarifikasi" ) )} -> 2024-01-01 | L4: {=IF( E4<>"Evening", E4, IFERROR( INDEX($E$2:$E$301, SMALL( IF( ($B$2:$B$301=B4) * ($C$2:$C$301=C4) * ($D$2:$D$301=D4) * ($F$2:$F$301=F4) * ($G$2:$G$301=G4) * ($H$2:$H$301=H4) * ($I$2:$I$301=I4) * ($J$2:$J$301=J4) * ($K$2:$K$301=K4) * ($E$2:$E$301<>"Evening"), ROW($E$2:$E$301)-ROW($E$2)+1, "" ), 1)), "Night" ) )} -> Night
A5: 2024-01-01 | B5: Pit C | C5: Seam 1 | D5: EX1100 | E5: Evening | F5: =F2 -> 713 | G5: 6438 | H5: 9.92 | I5: 1.86 | J5: 8.06 | K5: {=IF( ISNUMBER(DATEVALUE(A5)), TEXT(DATEVALUE(A5),"yyyy-mm-dd"), IFERROR( TEXT(INDEX($A$2:$A$301,MATCH(1, ($B$2:$B$301=B5) * ($C$2:$C$301=C5) * ($D$2:$D$301=D5) * ($E$2:$E$301=E5) * ($F$2:$F$301=F5) * ($G$2:$G$301=G5) * ($H$2:$H$301=H5) * ($I$2:$I$301=I5) * ($J$2:$J$301=J5),0)),"yyyy-mm-dd"), "Perlu Klarifikasi" ) )} -> 2024-01-01 | L5: {=IF( E5<>"Evening", E5, IFERROR( INDEX($E$2:$E$301, SMALL( IF( ($B$2:$B$301=B5) * ($C$2:$C$301=C5) * ($D$2:$D$301=D5) * ($F$2:$F$301=F5) * ($G$2:$G$301=G5) * ($H$2:$H$301=H5) * ($I$2:$I$301=I5) * ($J$2:$J$301=J5) * ($K$2:$K$301=K5) * ($E$2:$E$301<>"Evening"), ROW($E$2:$E$301)-ROW($E$2)+1, "" ), 1)), "Night" ) )} -> Night
A6: 2024-01-01 | B6: Pit C | C6: Seam 1 | D6: EX1100 | E6: Night | F6: 713 | G6: 6438 | H6: 9.92 | I6: 1.86 | J6: 8.06 | K6: {=IF( ISNUMBER(DATEVALUE(A6)), TEXT(DATEVALUE(A6),"yyyy-mm-dd"), IFERROR( TEXT(INDEX($A$2:$A$301,MATCH(1, ($B$2:$B$301=B6) * ($C$2:$C$301=C6) * ($D$2:$D$301=D6) * ($E$2:$E$301=E6) * ($F$2:$F$301=F6) * ($G$2:$G$301=G6) * ($H$2:$H$301=H6) * ($I$2:$I$301=I6) * ($J$2:$J$301=J6),0)),"yyyy-mm-dd"), "Perlu Klarifikasi" ) )} -> 2024-01-01 | L6: {=IF( E6<>"Evening", E6, IFERROR( INDEX($E$2:$E$301, SMALL( IF( ($B$2:$B$301=B6) * ($C$2:$C$301=C6) * ($D$2:$D$301=D6) * ($F$2:$F$301=F6) * ($G$2:$G$301=G6) * ($H$2:$H$301=H6) * ($I$2:$I$301=I6) * ($J$2:$J$301=J6) * ($K$2:$K$301=K6) * ($E$2:$E$301<>"Evening"), ROW($E$2:$E$301)-ROW($E$2)+1, "" ), 1)), "Night" ) )} -> Night
A7: 2024-01-01 | B7: Pit C | C7: Seam 2 | D7: EX1100 | E7: Night | F7: 1366 | G7: 1078 | H7: 4.44 | I7: 0.72 | J7: 3.72 | K7: {=IF( ISNUMBER(DATEVALUE(A7)), TEXT(DATEVALUE(A7),"yyyy-mm-dd"), IFERROR( TEXT(INDEX($A$2:$A$301,MATCH(1, ($B$2:$B$301=B7) * ($C$2:$C$301=C7) * ($D$2:$D$301=D7) * ($E$2:$E$301=E7) * ($F$2:$F$301=F7) * ($G$2:$G$301=G7) * ($H$2:$H$301=H7) * ($I$2:$I$301=I7) * ($J$2:$J$301=J7),0)),"yyyy-mm-dd"), "Perlu Klarifikasi" ) )} -> 2024-01-01 | L7: {=IF( E7<>"Evening", E7, IFERROR( INDEX($E$2:$E$301, SMALL( IF( ($B$2:$B$301=B7) * ($C$2:$C$301=C7) * ($D$2:$D$301=D7) * ($F$2:$F$301=F7) * ($G$2:$G$301=G7) * ($H$2:$H$301=H7) * ($I$2:$I$301=I7) * ($J$2:$J$301=J7) * ($K$2:$K$301=K7) * ($E$2:$E$301<>"Evening"), ROW($E$2:$E$301)-ROW($E$2)+1, "" ), 1)), "Night" ) )} -> Night
A8: 2024-01-01 | B8: Pit C | C8: Seam 1 | D8: EX1100 | E8: Night | F8: 713 | G8: 6438 | H8: 9.92 | I8: 1.86 | J8: 8.06 | K8: {=IF( ISNUMBER(DATEVALUE(A8)), TEXT(DATEVALUE(A8),"yyyy-mm-dd"), IFERROR( TEXT(INDEX($A$2:$A$301,MATCH(1, ($B$2:$B$301=B8) * ($C$2:$C$301=C8) * ($D$2:$D$301=D8) * ($E$2:$E$301=E8) * ($F$2:$F$301=F8) * ($G$2:$G$301=G8) * ($H$2:$H$301=H8) * ($I$2:$I$301=I8) * ($J$2:$J$301=J8),0)),"yyyy-mm-dd"), "Perlu Klarifikasi" ) )} -> 2024-01-01 | L8: {=IF( E8<>"Evening", E8, IFERROR( INDEX($E$2:$E$301, SMALL( IF( ($B$2:$B$301=B8) * ($C$2:$C$301=C8) * ($D$2:$D$301=D8) * ($F$2:$F$301=F8) * ($G$2:$G$301=G8) * ($H$2:$H$301=H8) * ($I$2:$I$301=I8) * ($J$2:$J$301=J8) * ($K$2:$K$301=K8) * ($E$2:$E$301<>"Evening"), ROW($E$2:$E$301)-ROW($E$2)+1, "" ), 1)), "Night" ) )} -> Night
A9: 2024-01-02 | B9: Pit A | C9: Seam 1 | D9: EX2500 | E9: Day | F9: 2612 | G9: 2675 | H9: 7.16 | I9: 1.5 | J9: 5.66 | K9: {=IF( ISNUMBER(DATEVALUE(A9)), TEXT(DATEVALUE(A9),"yyyy-mm-dd"), IFERROR( TEXT(INDEX($A$2:$A$301,MATCH(1, ($B$2:$B$301=B9) * ($C$2:$C$301=C9) * ($D$2:$D$301=D9) * ($E$2:$E$301=E9) * ($F$2:$F$301=F9) * ($G$2:$G$301=G9) * ($H$2:$H$301=H9) * ($I$2:$I$301=I9) * ($J$2:$J$301=J9),0)),"yyyy-mm-dd"), "Perlu Klarifikasi" ) )} -> 2024-01-02 | L9: {=IF( E9<>"Evening", E9, IFERROR( INDEX($E$2:$E$301, SMALL( IF( ($B$2:$B$301=B9) * ($C$2:$C$301=C9) * ($D$2:$D$301=D9) * ($F$2:$F$301=F9) * ($G$2:$G$301=G9) * ($H$2:$H$301=H9) * ($I$2:$I$301=I9) * ($J$2:$J$301=J9) * ($K$2:$K$301=K9) * ($E$2:$E$301<>"Evening"), ROW($E$2:$E$301)-ROW($E$2)+1, "" ), 1)), "Night" ) )} -> Day
A10: 2024-01-02 | B10: Pit A | C10: Seam 1 | D10: EX2500 | E10: Day | F10: 2612 | G10: 2675 | H10: 7.16 | I10: 1.5 | J10: 5.66 | K10: {=IF( ISNUMBER(DATEVALUE(A10)), TEXT(DATEVALUE(A10),"yyyy-mm-dd"), IFERROR( TEXT(INDEX($A$2:$A$301,MATCH(1, ($B$2:$B$301=B10) * ($C$2:$C$301=C10) * ($D$2:$D$301=D10) * ($E$2:$E$301=E10) * ($F$2:$F$301=F10) * ($G$2:$G$301=G10) * ($H$2:$H$301=H10) * ($I$2:$I$301=I10) * ($J$2:$J$301=J10),0)),"yyyy-mm-dd"), "Perlu Klarifikasi" ) )} -> 2024-01-02 | L10: {=IF( E10<>"Evening", E10, IFERROR( INDEX($E$2:$E$301, SMALL( IF( ($B$2:$B$301=B10) * ($C$2:$C$301=C10) * ($D$2:$D$301=D10) * ($F$2:$F$301=F10) * ($G$2:$G$301=G10) * ($H$2:$H$301=H10) * ($I$2:$I$301=I10) * ($J$2:$J$301=J10) * ($K$2:$K$301=K10) * ($E$2:$E$301<>"Evening"), ROW($E$2:$E$301)-ROW($E$2)+1, "" ), 1)), "Night" ) )} -> Day
A11: 2024-01-02 | B11: Pit B | C11: Seam 2 | D11: EX2500 | E11: Day | F11: 3737 | G11: 269 | H11: 9.95 | I11: 0.78 | J11: 9.17 | K11: {=IF( ISNUMBER(DATEVALUE(A11)), TEXT(DATEVALUE(A11),"yyyy-mm-dd"), IFERROR( TEXT(INDEX($A$2:$A$301,MATCH(1, ($B$2:$B$301=B11) * ($C$2:$C$301=C11) * ($D$2:$D$301=D11) * ($E$2:$E$301=E11) * ($F$2:$F$301=F11) * ($G$2:$G$301=G11) * ($H$2:$H$301=H11) * ($I$2:$I$301=I11) * ($J$2:$J$301=J11),0)),"yyyy-mm-dd"), "Perlu Klarifikasi" ) )} -> 2024-01-02 | L11: {=IF( E11<>"Evening", E11, IFERROR( INDEX($E$2:$E$301, SMALL( IF( ($B$2:$B$301=B11) * ($C$2:$C$301=C11) * ($D$2:$D$301=D11) * ($F$2:$F$301=F11) * ($G$2:$G$301=G11) * ($H$2:$H$301=H11) * ($I$2:$I$301=I11) * ($J$2:$J$301=J11) * ($K$2:$K$301=K11) * ($E$2:$E$301<>"Evening"), ROW($E$2:$E$301)-ROW($E$2)+1, "" ), 1)), "Night" ) )} -> Day
A12: 2024/13/40 | B12: Pit B | C12: Seam 2 | D12: EX2500 | E12: Day | F12: 3737 | G12: 269 | H12: 9.95 | I12: 0.78 | J12: 9.17 | K12: {=IF( ISNUMBER(DATEVALUE(A12)), TEXT(DATEVALUE(A12),"yyyy-mm-dd"), IFERROR( TEXT(INDEX($A$2:$A$301,MATCH(1, ($B$2:$B$301=B12) * ($C$2:$C$301=C12) * ($D$2:$D$301=D12) * ($E$2:$E$301=E12) * ($F$2:$F$301=F12) * ($G$2:$G$301=G12) * ($H$2:$H$301=H12) * ($I$2:$I$301=I12) * ($J$2:$J$301=J12),0)),"yyyy-mm-dd"), "Perlu Klarifikasi" ) )} -> 2024-01-02 | L12: {=IF( E12<>"Evening", E12, IFERROR( INDEX($E$2:$E$301, SMALL( IF( ($B$2:$B$301=B12) * ($C$2:$C$301=C12) * ($D$2:$D$301=D12) * ($F$2:$F$301=F12) * ($G$2:$G$301=G12) * ($H$2:$H$301=H12) * ($I$2:$I$301=I12) * ($J$2:$J$301=J12) * ($K$2:$K$301=K12) * ($E$2:$E$301<>"Evening"), ROW($E$2:$E$301)-ROW($E$2)+1, "" ), 1)), "Night" ) )} -> Day
A13: 2024-01-02 | B13: Pit C | C13: Seam 2 | D13: EX2500 | E13: Day | F13: 7669 | G13: 4949 | H13: 7.54 | I13: 0.96 | J13: 6.58 | K13: {=IF( ISNUMBER(DATEVALUE(A13)), TEXT(DATEVALUE(A13),"yyyy-mm-dd"), IFERROR( TEXT(INDEX($A$2:$A$301,MATCH(1, ($B$2:$B$301=B13) * ($C$2:$C$301=C13) * ($D$2:$D$301=D13) * ($E$2:$E$301=E13) * ($F$2:$F$301=F13) * ($G$2:$G$301=G13) * ($H$2:$H$301=H13) * ($I$2:$I$301=I13) * ($J$2:$J$301=J13),0)),"yyyy-mm-dd"), "Perlu Klarifikasi" ) )} -> 2024-01-02 | L13: {=IF( E13<>"Evening", E13, IFERROR( INDEX($E$2:$E$301, SMALL( IF( ($B$2:$B$301=B13) * ($C$2:$C$301=C13) * ($D$2:$D$301=D13) * ($F$2:$F$301=F13) * ($G$2:$G$301=G13) * ($H$2:$H$301=H13) * ($I$2:$I$301=I13) * ($J$2:$J$301=J13) * ($K$2:$K$301=K13) * ($E$2:$E$301<>"Evening"), ROW($E$2:$E$301)-ROW($E$2)+1, "" ), 1)), "Night" ) )} -> Day
A14: 2024-01-02 | B14: Pit B | C14: Seam 2 | D14: EX2500 | E14: Evening | F14: 3737 | G14: 269 | H14: 9.95 | I14: 0.78 | J14: 9.17 | K14: {=IF( ISNUMBER(DATEVALUE(A14)), TEXT(DATEVALUE(A14),"yyyy-mm-dd"), IFERROR( TEXT(INDEX($A$2:$A$301,MATCH(1, ($B$2:$B$301=B14) * ($C$2:$C$301=C14) * ($D$2:$D$301=D14) * ($E$2:$E$301=E14) * ($F$2:$F$301=F14) * ($G$2:$G$301=G14) * ($H$2:$H$301=H14) * ($I$2:$I$301=I14) * ($J$2:$J$301=J14),0)),"yyyy-mm-dd"), "Perlu Klarifikasi" ) )} -> 2024-01-02 | L14: {=IF( E14<>"Evening", E14, IFERROR( INDEX($E$2:$E$301, SMALL( IF( ($B$2:$B$301=B14) * ($C$2:$C$301=C14) * ($D$2:$D$301=D14) * ($F$2:$F$301=F14) * ($G$2:$G$301=G14) * ($H$2:$H$301=H14) * ($I$2:$I$301=I14) * ($J$2:$J$301=J14) * ($K$2:$K$301=K14) * ($E$2:$E$301<>"Evening"), ROW($E$2:$E$301)-ROW($E$2)+1, "" ), 1)), "Night" ) )} -> Day
A15: 2024/13/40 | B15: Pit B | C15: Seam 2 | D15: EX2500 | E15: Day | F15: 3737 | G15: 269 | H15: 9.95 | I15: 0.78 | J15: 9.17 | K15: {=IF( ISNUMBER(DATEVALUE(A15)), TEXT(DATEVALUE(A15),"yyyy-mm-dd"), IFERROR( TEXT(INDEX($A$2:$A$301,MATCH(1, ($B$2:$B$301=B15) * ($C$2:$C$301=C15) * ($D$2:$D$301=D15) * ($E$2:$E$301=E15) * ($F$2:$F$301=F15) * ($G$2:$G$301=G15) * ($H$2:$H$301=H15) * ($I$2:$I$301=I15) * ($J$2:$J$301=J15),0)),"yyyy-mm-dd"), "Perlu Klarifikasi" ) )} -> 2024-01-02 | L15: {=IF( E15<>"Evening", E15, IFERROR( INDEX($E$2:$E$301, SMALL( IF( ($B$2:$B$301=B15) * ($C$2:$C$301=C15) * ($D$2:$D$301=D15) * ($F$2:$F$301=F15) * ($G$2:$G$301=G15) * ($H$2:$H$301=H15) * ($I$2:$I$301=I15) * ($J$2:$J$301=J15) * ($K$2:$K$301=K15) * ($E$2:$E$301<>"Evening"), ROW($E$2:$E$301)-ROW($E$2)+1, "" ), 1)), "Night" ) )} -> Day
A16: 2024-01-03 | B16: Pit A | C16: Seam 1 | D16: EX1200 | E16: Night | F16: 684 | G16: 1349 | H16: 5.43 | I16: 0.27 | J16: 5.16 | K16: {=IF( ISNUMBER(DATEVALUE(A16)), TEXT(DATEVALUE(A16),"yyyy-mm-dd"), IFERROR( TEXT(INDEX($A$2:$A$301,MATCH(1, ($B$2:$B$301=B16) * ($C$2:$C$301=C16) * ($D$2:$D$301=D16) * ($E$2:$E$301=E16) * ($F$2:$F$301=F16) * ($G$2:$G$301=G16) * ($H$2:$H$301=H16) * ($I$2:$I$301=I16) * ($J$2:$J$301=J16),0)),"yyyy-mm-dd"), "Perlu Klarifikasi" ) )} -> 2024-01-03 | L16: {=IF( E16<>"Evening", E16, IFERROR( INDEX($E$2:$E$301, SMALL( IF( ($B$2:$B$301=B16) * ($C$2:$C$301=C16) * ($D$2:$D$301=D16) * ($F$2:$F$301=F16) * ($G$2:$G$301=G16) * ($H$2:$H$301=H16) * ($I$2:$I$301=I16) * ($J$2:$J$301=J16) * ($K$2:$K$301=K16) * ($E$2:$E$301<>"Evening"), ROW($E$2:$E$301)-ROW($E$2)+1, "" ), 1)), "Night" ) )} -> Night
A17: 2024-01-03 | B17: Pit A | C17: Seam 2 | D17: EX1200 | E17: Day | F17: 8978 | G17: 3637 | H17: 4.71 | I17: 0.08 | J17: 4.63 | K17: {=IF( ISNUMBER(DATEVALUE(A17)), TEXT(DATEVALUE(A17),"yyyy-mm-dd"), IFERROR( TEXT(INDEX($A$2:$A$301,MATCH(1, ($B$2:$B$301=B17) * ($C$2:$C$301=C17) * ($D$2:$D$301=D17) * ($E$2:$E$301=E17) * ($F$2:$F$301=F17) * ($G$2:$G$301=G17) * ($H$2:$H$301=H17) * ($I$2:$I$301=I17) * ($J$2:$J$301=J17),0)),"yyyy-mm-dd"), "Perlu Klarifikasi" ) )} -> 2024-01-03 | L17: {=IF( E17<>"Evening", E17, IFERROR( INDEX($E$2:$E$301, SMALL( IF( ($B$2:$B$301=B17) * ($C$2:$C$301=C17) * ($D$2:$D$301=D17) * ($F$2:$F$301=F17) * ($G$2:$G$301=G17) * ($H$2:$H$301=H17) * ($I$2:$I$301=I17) * ($J$2:$J$301=J17) * ($K$2:$K$301=K17) * ($E$2:$E$301<>"Evening"), ROW($E$2:$E$301)-ROW($E$2)+1, "" ), 1)), "Night" ) )} -> Day
... A26: 2024-01-03 | B26: Pit A | C26: Seam 2 | D26: EX1200 | E26: Day | F26: 8978 | G26: 3637 | H26: 4.71 | I26: 0.08 | J26: 4.63 | K26: {=IF( ISNUMBER(DATEVALUE(A26)), TEXT(DATEVALUE(A26),"yyyy-mm-dd"), IFERROR( TEXT(INDEX($A$2:$A$301,MATCH(1, ($B$2:$B$301=B26) * ($C$2:$C$301=C26) * ($D$2:$D$301=D26) * ($E$2:$E$301=E26) * ($F$2:$F$301=F26) * ($G$2:$G$301=G26) * ($H$2:$H$301=H26) * ($I$2:$I$301=I26) * ($J$2:$J$301=J26),0)),"yyyy-mm-dd"), "Perlu Klarifikasi" ) )} -> 2024-01-03 | L26: {=IF( E26<>"Evening", E26, IFERROR( INDEX($E$2:$E$301, SMALL( IF( ($B$2:$B$301=B26) * ($C$2:$C$301=C26) * ($D$2:$D$301=D26) * ($F$2:$F$301=F26) * ($G$2:$G$301=G26) * ($H$2:$H$301=H26) * ($I$2:$I$301=I26) * ($J$2:$J$301=J26) * ($K$2:$K$301=K26) * ($E$2:$E$301<>"Evening"), ROW($E$2:$E$301)-ROW($E$2)+1, "" ), 1)), "Night" ) )} -> Day
A27: 2024-01-03 | B27: Pit A | C27: Seam 2 | D27: EX1200 | E27: Day | F27: 8978 | G27: =G26 -> 3637 | H27: 4.71 | I27: 0.08 | J27: 4.63 | K27: {=IF( ISNUMBER(DATEVALUE(A27)), TEXT(DATEVALUE(A27),"yyyy-mm-dd"), IFERROR( TEXT(INDEX($A$2:$A$301,MATCH(1, ($B$2:$B$301=B27) * ($C$2:$C$301=C27) * ($D$2:$D$301=D27) * ($E$2:$E$301=E27) * ($F$2:$F$301=F27) * ($G$2:$G$301=G27) * ($H$2:$H$301=H27) * ($I$2:$I$301=I27) * ($J$2:$J$301=J27),0)),"yyyy-mm-dd"), "Perlu Klarifikasi" ) )} -> 2024-01-03 | L27: {=IF( E27<>"Evening", E27, IFERROR( INDEX($E$2:$E$301, SMALL( IF( ($B$2:$B$301=B27) * ($C$2:$C$301=C27) * ($D$2:$D$301=D27) * ($F$2:$F$301=F27) * ($G$2:$G$301=G27) * ($H$2:$H$301=H27) * ($I$2:$I$301=I27) * ($J$2:$J$301=J27) * ($K$2:$K$301=K27) * ($E$2:$E$301<>"Evening"), ROW($E$2:$E$301)-ROW($E$2)+1, "" ), 1)), "Night" ) )} -> Day
A28: 2024-01-03 | B28: Pit A | C28: Seam 2 | D28: EX1200 | E28: Night | F28: 2604 | G28: 1318 | H28: 6.25 | I28: 1.14 | J28: 5.11 | K28: {=IF( ISNUMBER(DATEVALUE(A28)), TEXT(DATEVALUE(A28),"yyyy-mm-dd"), IFERROR( TEXT(INDEX($A$2:$A$301,MATCH(1, ($B$2:$B$301=B28) * ($C$2:$C$301=C28) * ($D$2:$D$301=D28) * ($E$2:$E$301=E28) * ($F$2:$F$301=F28) * ($G$2:$G$301=G28) * ($H$2:$H$301=H28) * ($I$2:$I$301=I28) * ($J$2:$J$301=J28),0)),"yyyy-mm-dd"), "Perlu Klarifikasi" ) )} -> 2024-01-03 | L28: {=IF( E28<>"Evening", E28, IFERROR( INDEX($E$2:$E$301, SMALL( IF( ($B$2:$B$301=B28) * ($C$2:$C$301=C28) * ($D$2:$D$301=D28) * ($F$2:$F$301=F28) * ($G$2:$G$301=G28) * ($H$2:$H$301=H28) * ($I$2:$I$301=I28) * ($J$2:$J$301=J28) * ($K$2:$K$301=K28) * ($E$2:$E$301<>"Evening"), ROW($E$2:$E$301)-ROW($E$2)+1, "" ), 1)), "Night" ) )} -> Night
A29: 2024-01-03 | B29: Pit B | C29: Seam 2 | D29: EX2500 | E29: Night | F29: 3710 | G29: 3388 | H29: 8.73 | I29: 1.18 | J29: 7.55 | K29: {=IF( ISNUMBER(DATEVALUE(A29)), TEXT(DATEVALUE(A29),"yyyy-mm-dd"), IFERROR( TEXT(INDEX($A$2:$A$301,MATCH(1, ($B$2:$B$301=B29) * ($C$2:$C$301=C29) * ($D$2:$D$301=D29) * ($E$2:$E$301=E29) * ($F$2:$F$301=F29) * ($G$2:$G$301=G29) * ($H$2:$H$301=H29) * ($I$2:$I$301=I29) * ($J$2:$J$301=J29),0)),"yyyy-mm-dd"), "Perlu Klarifikasi" ) )} -> 2024-01-03 | L29: {=IF( E29<>"Evening", E29, IFERROR( INDEX($E$2:$E$301, SMALL( IF( ($B$2:$B$301=B29) * ($C$2:$C$301=C29) * ($D$2:$D$301=D29) * ($F$2:$F$301=F29) * ($G$2:$G$301=G29) * ($H$2:$H$301=H29) * ($I$2:$I$301=I29) * ($J$2:$J$301=J29) * ($K$2:$K$301=K29) * ($E$2:$E$301<>"Evening"), ROW($E$2:$E$301)-ROW($E$2)+1, "" ), 1)), "Night" ) )} -> Night
A30: 2024-01-04 | B30: Pit C | C30: Seam 3 | D30: EX1200 | E30: Evening | F30: 5683 | G30: 5055 | H30: 4.59 | I30: 0.17 | J30: 4.42 | K30: {=IF( ISNUMBER(DATEVALUE(A30)), TEXT(DATEVALUE(A30),"yyyy-mm-dd"), IFERROR( TEXT(INDEX($A$2:$A$301,MATCH(1, ($B$2:$B$301=B30) * ($C$2:$C$301=C30) * ($D$2:$D$301=D30) * ($E$2:$E$301=E30) * ($F$2:$F$301=F30) * ($G$2:$G$301=G30) * ($H$2:$H$301=H30) * ($I$2:$I$301=I30) * ($J$2:$J$301=J30),0)),"yyyy-mm-dd"), "Perlu Klarifikasi" ) )} -> 2024-01-04 | L30: {=IF( E30<>"Evening", E30, IFERROR( INDEX($E$2:$E$301, SMALL( IF( ($B$2:$B$301=B30) * ($C$2:$C$301=C30) * ($D$2:$D$301=D30) * ($F$2:$F$301=F30) * ($G$2:$G$301=G30) * ($H$2:$H$301=H30) * ($I$2:$I$301=I30) * ($J$2:$J$301=J30) * ($K$2:$K$301=K30) * ($E$2:$E$301<>"Evening"), ROW($E$2:$E$301)-ROW($E$2)+1, "" ), 1)), "Night" ) )} -> Night
A31: 2024-01-05 | B31: Pit B | C31: Seam 1 | D31: EX2500 | E31: Night | F31: 4512 | G31: 1543 | H31: 5.16 | I31: 0.03 | J31: 5.13 | K31: {=IF( ISNUMBER(DATEVALUE(A31)), TEXT(DATEVALUE(A31),"yyyy-mm-dd"), IFERROR( TEXT(INDEX($A$2:$A$301,MATCH(1, ($B$2:$B$301=B31) * ($C$2:$C$301=C31) * ($D$2:$D$301=D31) * ($E$2:$E$301=E31) * ($F$2:$F$301=F31) * ($G$2:$G$301=G31) * ($H$2:$H$301=H31) * ($I$2:$I$301=I31) * ($J$2:$J$301=J31),0)),"yyyy-mm-dd"), "Perlu Klarifikasi" ) )} -> 2024-01-05 | L31: {=IF( E31<>"Evening", E31, IFERROR( INDEX($E$2:$E$301, SMALL( IF( ($B$2:$B$301=B31) * ($C$2:$C$301=C31) * ($D$2:$D$301=D31) * ($F$2:$F$301=F31) * ($G$2:$G$301=G31) * ($H$2:$H$301=H31) * ($I$2:$I$301=I31) * ($J$2:$J$301=J31) * ($K$2:$K$301=K31) * ($E$2:$E$301<>"Evening"), ROW($E$2:$E$301)-ROW($E$2)+1, "" ), 1)), "Night" ) )} -> Night
A32: 2024-01-07 | B32: Pit C | C32: Seam 2 | D32: EX1200 | E32: Day | F32: 8608 | G32: 1381 | H32: 5.24 | I32: 0.17 | J32: 5.07 | K32: {=IF( ISNUMBER(DATEVALUE(A32)), TEXT(DATEVALUE(A32),"yyyy-mm-dd"), IFERROR( TEXT(INDEX($A$2:$A$301,MATCH(1, ($B$2:$B$301=B32) * ($C$2:$C$301=C32) * ($D$2:$D$301=D32) * ($E$2:$E$301=E32) * ($F$2:$F$301=F32) * ($G$2:$G$301=G32) * ($H$2:$H$301=H32) * ($I$2:$I$301=I32) * ($J$2:$J$301=J32),0)),"yyyy-mm-dd"), "Perlu Klarifikasi" ) )} -> 2024-01-07 | L32: {=IF( E32<>"Evening", E32, IFERROR( INDEX($E$2:$E$301, SMALL( IF( ($B$2:$B$301=B32) * ($C$2:$C$301=C32) * ($D$2:$D$301=D32) * ($F$2:$F$301=F32) * ($G$2:$G$301=G32) * ($H$2:$H$301=H32) * ($I$2:$I$301=I32) * ($J$2:$J$301=J32) * ($K$2:$K$301=K32) * ($E$2:$E$301<>"Evening"), ROW($E$2:$E$301)-ROW($E$2)+1, "" ), 1)), "Night" ) )} -> Day
A33: 2024-01-07 | B33: Pit C | C33: Seam 2 | D33: EX1200 | E33: Day | F33: 8608 | G33: 1381 | H33: 5.24 | I33: 0.17 | J33: 5.07 | K33: {=IF( ISNUMBER(DATEVALUE(A33)), TEXT(DATEVALUE(A33),"yyyy-mm-dd"), IFERROR( TEXT(INDEX($A$2:$A$301,MATCH(1, ($B$2:$B$301=B33) * ($C$2:$C$301=C33) * ($D$2:$D$301=D33) * ($E$2:$E$301=E33) * ($F$2:$F$301=F33) * ($G$2:$G$301=G33) * ($H$2:$H$301=H33) * ($I$2:$I$301=I33) * ($J$2:$J$301=J33),0)),"yyyy-mm-dd"), "Perlu Klarifikasi" ) )} -> 2024-01-07 | L33: {=IF( E33<>"Evening", E33, IFERROR( INDEX($E$2:$E$301, SMALL( IF( ($B$2:$B$301=B33) * ($C$2:$C$301=C33) * ($D$2:$D$301=D33) * ($F$2:$F$301=F33) * ($G$2:$G$301=G33) * ($H$2:$H$301=H33) * ($I$2:$I$301=I33) * ($J$2:$J$301=J33) * ($K$2:$K$301=K33) * ($E$2:$E$301<>"Evening"), ROW($E$2:$E$301)-ROW($E$2)+1, "" ), 1)), "Night" ) )} -> Day
A34: 2024-01-07 | B34: Pit A | C34: Seam 1 | D34: EX1200 | E34: Night | F34: 2268 | G34: 5211 | H34: 9.78 | I34: 0.33 | J34: 9.45 | K34: {=IF( ISNUMBER(DATEVALUE(A34)), TEXT(DATEVALUE(A34),"yyyy-mm-dd"), IFERROR( TEXT(INDEX($A$2:$A$301,MATCH(1, ($B$2:$B$301=B34) * ($C$2:$C$301=C34) * ($D$2:$D$301=D34) * ($E$2:$E$301=E34) * ($F$2:$F$301=F34) * ($G$2:$G$301=G34) * ($H$2:$H$301=H34) * ($I$2:$I$301=I34) * ($J$2:$J$301=J34),0)),"yyyy-mm-dd"), "Perlu Klarifikasi" ) )} -> 2024-01-07 | L34: {=IF( E34<>"Evening", E34, IFERROR( INDEX($E$2:$E$301, SMALL( IF( ($B$2:$B$301=B34) * ($C$2:$C$301=C34) * ($D$2:$D$301=D34) * ($F$2:$F$301=F34) * ($G$2:$G$301=G34) * ($H$2:$H$301=H34) * ($I$2:$I$301=I34) * ($J$2:$J$301=J34) * ($K$2:$K$301=K34) * ($E$2:$E$301<>"Evening"), ROW($E$2:$E$301)-ROW($E$2)+1, "" ), 1)), "Night" ) )} -> Night
A35: 2024-01-09 | B35: Pit C | C35: Seam 3 | D35: EX1100 | E35: Day | F35: 3338 | G35: 3878 | H35: 9.27 | I35: 0.35 | J35: 8.92 | K35: {=IF( ISNUMBER(DATEVALUE(A35)), TEXT(DATEVALUE(A35),"yyyy-mm-dd"), IFERROR( TEXT(INDEX($A$2:$A$301,MATCH(1, ($B$2:$B$301=B35) * ($C$2:$C$301=C35) * ($D$2:$D$301=D35) * ($E$2:$E$301=E35) * ($F$2:$F$301=F35) * ($G$2:$G$301=G35) * ($H$2:$H$301=H35) * ($I$2:$I$301=I35) * ($J$2:$J$301=J35),0)),"yyyy-mm-dd"), "Perlu Klarifikasi" ) )} -> 2024-01-09 | L35: {=IF( E35<>"Evening", E35, IFERROR( INDEX($E$2:$E$301, SMALL( IF( ($B$2:$B$301=B35) * ($C$2:$C$301=C35) * ($D$2:$D$301=D35) * ($F$2:$F$301=F35) * ($G$2:$G$301=G35) * ($H$2:$H$301=H35) * ($I$2:$I$301=I35) * ($J$2:$J$301=J35) * ($K$2:$K$301=K35) * ($E$2:$E$301<>"Evening"), ROW($E$2:$E$301)-ROW($E$2)+1, "" ), 1)), "Night" ) )} -> Day
A36: 2024-01-09 | B36: Pit A | C36: Seam 3 | D36: EX1200 | E36: Night | F36: 938 | G36: 2671 | H36: 6.8 | I36: 0.97 | J36: 5.83 | K36: {=IF( ISNUMBER(DATEVALUE(A36)), TEXT(DATEVALUE(A36),"yyyy-mm-dd"), IFERROR( TEXT(INDEX($A$2:$A$301,MATCH(1, ($B$2:$B$301=B36) * ($C$2:$C$301=C36) * ($D$2:$D$301=D36) * ($E$2:$E$301=E36) * ($F$2:$F$301=F36) * ($G$2:$G$301=G36) * ($H$2:$H$301=H36) * ($I$2:$I$301=I36) * ($J$2:$J$301=J36),0)),"yyyy-mm-dd"), "Perlu Klarifikasi" ) )} -> 2024-01-09 | L36: {=IF( E36<>"Evening", E36, IFERROR( INDEX($E$2:$E$301, SMALL( IF( ($B$2:$B$301=B36) * ($C$2:$C$301=C36) * ($D$2:$D$301=D36) * ($F$2:$F$301=F36) * ($G$2:$G$301=G36) * ($H$2:$H$301=H36) * ($I$2:$I$301=I36) * ($J$2:$J$301=J36) * ($K$2:$K$301=K36) * ($E$2:$E$301<>"Evening"), ROW($E$2:$E$301)-ROW($E$2)+1, "" ), 1)), "Night" ) )} -> Night
A37: 2024-01-09 | B37: Pit C | C37: Seam 3 | D37: EX1100 | E37: Day | F37: 3338 | G37: 3878 | H37: 9.27 | I37: 0.35 | J37: 8.92 | K37: {=IF( ISNUMBER(DATEVALUE(A37)), TEXT(DATEVALUE(A37),"yyyy-mm-dd"), IFERROR( TEXT(INDEX($A$2:$A$301,MATCH(1, ($B$2:$B$301=B37) * ($C$2:$C$301=C37) * ($D$2:$D$301=D37) * ($E$2:$E$301=E37) * ($F$2:$F$301=F37) * ($G$2:$G$301=G37) * ($H$2:$H$301=H37) * ($I$2:$I$301=I37) * ($J$2:$J$301=J37),0)),"yyyy-mm-dd"), "Perlu Klarifikasi" ) )} -> 2024-01-09 | L37: {=IF( E37<>"Evening", E37, IFERROR( INDEX($E$2:$E$301, SMALL( IF( ($B$2:$B$301=B37) * ($C$2:$C$301=C37) * ($D$2:$D$301=D37) * ($F$2:$F$301=F37) * ($G$2:$G$301=G37) * ($H$2:$H$301=H37) * ($I$2:$I$301=I37) * ($J$2:$J$301=J37) * ($K$2:$K$301=K37) * ($E$2:$E$301<>"Evening"), ROW($E$2:$E$301)-ROW($E$2)+1, "" ), 1)), "Night" ) )} -> Day
A38: 2024-01-09 | B38: Pit A | C38: Seam 3 | D38: EX1200 | E38: Night | F38: 938 | G38: 2671 | H38: 6.8 | I38: 0.97 | J38: 5.83 | K38: {=IF( ISNUMBER(DATEVALUE(A38)), TEXT(DATEVALUE(A38),"yyyy-mm-dd"), IFERROR( TEXT(INDEX($A$2:$A$301,MATCH(1, ($B$2:$B$301=B38) * ($C$2:$C$301=C38) * ($D$2:$D$301=D38) * ($E$2:$E$301=E38) * ($F$2:$F$301=F38) * ($G$2:$G$301=G38) * ($H$2:$H$301=H38) * ($I$2:$I$301=I38) * ($J$2:$J$301=J38),0)),"yyyy-mm-dd"), "Perlu Klarifikasi" ) )} -> 2024-01-09 | L38: {=IF( E38<>"Evening", E38, IFERROR( INDEX($E$2:$E$301, SMALL( IF( ($B$2:$B$301=B38) * ($C$2:$C$301=C38) * ($D$2:$D$301=D38) * ($F$2:$F$301=F38) * ($G$2:$G$301=G38) * ($H$2:$H$301=H38) * ($I$2:$I$301=I38) * ($J$2:$J$301=J38) * ($K$2:$K$301=K38) * ($E$2:$E$301<>"Evening"), ROW($E$2:$E$301)-ROW($E$2)+1, "" ), 1)), "Night" ) )} -> Night
A39: 2024-01-09 | B39: Pit C | C39: Seam 3 | D39: EX1100 | E39: Day | F39: 3338 | G39: 3878 | H39: 9.27 | I39: 0.35 | J39: 8.92 | K39: {=IF( ISNUMBER(DATEVALUE(A39)), TEXT(DATEVALUE(A39),"yyyy-mm-dd"), IFERROR( TEXT(INDEX($A$2:$A$301,MATCH(1, ($B$2:$B$301=B39) * ($C$2:$C$301=C39) * ($D$2:$D$301=D39) * ($E$2:$E$301=E39) * ($F$2:$F$301=F39) * ($G$2:$G$301=G39) * ($H$2:$H$301=H39) * ($I$2:$I$301=I39) * ($J$2:$J$301=J39),0)),"yyyy-mm-dd"), "Perlu Klarifikasi" ) )} -> 2024-01-09 | L39: {=IF( E39<>"Evening", E39, IFERROR( INDEX($E$2:$E$301, SMALL( IF( ($B$2:$B$301=B39) * ($C$2:$C$301=C39) * ($D$2:$D$301=D39) * ($F$2:$F$301=F39) * ($G$2:$G$301=G39) * ($H$2:$H$301=H39) * ($I$2:$I$301=I39) * ($J$2:$J$301=J39) * ($K$2:$K$301=K39) * ($E$2:$E$301<>"Evening"), ROW($E$2:$E$301)-ROW($E$2)+1, "" ), 1)), "Night" ) )} -> Day
... A52: 2024-01-14 | B52: Pit A | C52: Seam 1 | D52: EX2500 | E52: Day | F52: 6140 | G52: 68 | H52: 5.95 | I52: 0.06 | J52: 5.89 | K52: {=IF( ISNUMBER(DATEVALUE(A52)), TEXT(DATEVALUE(A52),"yyyy-mm-dd"), IFERROR( TEXT(INDEX($A$2:$A$301,MATCH(1, ($B$2:$B$301=B52) * ($C$2:$C$301=C52) * ($D$2:$D$301=D52) * ($E$2:$E$301=E52) * ($F$2:$F$301=F52) * ($G$2:$G$301=G52) * ($H$2:$H$301=H52) * ($I$2:$I$301=I52) * ($J$2:$J$301=J52),0)),"yyyy-mm-dd"), "Perlu Klarifikasi" ) )} -> 2024-01-14 | L52: {=IF( E52<>"Evening", E52, IFERROR( INDEX($E$2:$E$301, SMALL( IF( ($B$2:$B$301=B52) * ($C$2:$C$301=C52) * ($D$2:$D$301=D52) * ($F$2:$F$301=F52) * ($G$2:$G$301=G52) * ($H$2:$H$301=H52) * ($I$2:$I$301=I52) * ($J$2:$J$301=J52) * ($K$2:$K$301=K52) * ($E$2:$E$301<>"Evening"), ROW($E$2:$E$301)-ROW($E$2)+1, "" ), 1)), "Night" ) )} -> Day
A53: 2024-01-14 | B53: Pit C | C53: Seam 1 | D53: EX1100 | E53: Night | F53: 8322 | G53: =G56 -> 5039 | H53: 9.36 | I53: 1.99 | J53: 7.37 | K53: {=IF( ISNUMBER(DATEVALUE(A53)), TEXT(DATEVALUE(A53),"yyyy-mm-dd"), IFERROR( TEXT(INDEX($A$2:$A$301,MATCH(1, ($B$2:$B$301=B53) * ($C$2:$C$301=C53) * ($D$2:$D$301=D53) * ($E$2:$E$301=E53) * ($F$2:$F$301=F53) * ($G$2:$G$301=G53) * ($H$2:$H$301=H53) * ($I$2:$I$301=I53) * ($J$2:$J$301=J53),0)),"yyyy-mm-dd"), "Perlu Klarifikasi" ) )} -> 2024-01-14 | L53: {=IF( E53<>"Evening", E53, IFERROR( INDEX($E$2:$E$301, SMALL( IF( ($B$2:$B$301=B53) * ($C$2:$C$301=C53) * ($D$2:$D$301=D53) * ($F$2:$F$301=F53) * ($G$2:$G$301=G53) * ($H$2:$H$301=H53) * ($I$2:$I$301=I53) * ($J$2:$J$301=J53) * ($K$2:$K$301=K53) * ($E$2:$E$301<>"Evening"), ROW($E$2:$E$301)-ROW($E$2)+1, "" ), 1)), "Night" ) )} -> Night
A54: 2024-01-14 | B54: Pit A | C54: Seam 1 | D54: EX2500 | E54: Day | F54: 6140 | G54: 68 | H54: 5.95 | I54: 0.06 | J54: 5.89 | K54: {=IF( ISNUMBER(DATEVALUE(A54)), TEXT(DATEVALUE(A54),"yyyy-mm-dd"), IFERROR( TEXT(INDEX($A$2:$A$301,MATCH(1, ($B$2:$B$301=B54) * ($C$2:$C$301=C54) * ($D$2:$D$301=D54) * ($E$2:$E$301=E54) * ($F$2:$F$301=F54) * ($G$2:$G$301=G54) * ($H$2:$H$301=H54) * ($I$2:$I$301=I54) * ($J$2:$J$301=J54),0)),"yyyy-mm-dd"), "Perlu Klarifikasi" ) )} -> 2024-01-14 | L54: {=IF( E54<>"Evening", E54, IFERROR( INDEX($E$2:$E$301, SMALL( IF( ($B$2:$B$301=B54) * ($C$2:$C$301=C54) * ($D$2:$D$301=D54) * ($F$2:$F$301=F54) * ($G$2:$G$301=G54) * ($H$2:$H$301=H54) * ($I$2:$I$301=I54) * ($J$2:$J$301=J54) * ($K$2:$K$301=K54) * ($E$2:$E$301<>"Evening"), ROW($E$2:$E$301)-ROW($E$2)+1, "" ), 1)), "Night" ) )} -> Day
A55: 2024/13/40 | B55: Pit A | C55: Seam 1 | D55: EX2500 | E55: Day | F55: 6140 | G55: 68 | H55: 5.95 | I55: 0.06 | J55: 5.89 | K55: {=IF( ISNUMBER(DATEVALUE(A55)), TEXT(DATEVALUE(A55),"yyyy-mm-dd"), IFERROR( TEXT(INDEX($A$2:$A$301,MATCH(1, ($B$2:$B$301=B55) * ($C$2:$C$301=C55) * ($D$2:$D$301=D55) * ($E$2:$E$301=E55) * ($F$2:$F$301=F55) * ($G$2:$G$301=G55) * ($H$2:$H$301=H55) * ($I$2:$I$301=I55) * ($J$2:$J$301=J55),0)),"yyyy-mm-dd"), "Perlu Klarifikasi" ) )} -> 2024-01-14 | L55: {=IF( E55<>"Evening", E55, IFERROR( INDEX($E$2:$E$301, SMALL( IF( ($B$2:$B$301=B55) * ($C$2:$C$301=C55) * ($D$2:$D$301=D55) * ($F$2:$F$301=F55) * ($G$2:$G$301=G55) * ($H$2:$H$301=H55) * ($I$2:$I$301=I55) * ($J$2:$J$301=J55) * ($K$2:$K$301=K55) * ($E$2:$E$301<>"Evening"), ROW($E$2:$E$301)-ROW($E$2)+1, "" ), 1)), "Night" ) )} -> Day
A56: 2024-01-14 | B56: Pit C | C56: Seam 1 | D56: EX1100 | E56: Night | F56: 8322 | G56: 5039 | H56: 9.36 | I56: 1.99 | J56: 7.37 | K56: {=IF( ISNUMBER(DATEVALUE(A56)), TEXT(DATEVALUE(A56),"yyyy-mm-dd"), IFERROR( TEXT(INDEX($A$2:$A$301,MATCH(1, ($B$2:$B$301=B56) * ($C$2:$C$301=C56) * ($D$2:$D$301=D56) * ($E$2:$E$301=E56) * ($F$2:$F$301=F56) * ($G$2:$G$301=G56) * ($H$2:$H$301=H56) * ($I$2:$I$301=I56) * ($J$2:$J$301=J56),0)),"yyyy-mm-dd"), "Perlu Klarifikasi" ) )} -> 2024-01-14 | L56: {=IF( E56<>"Evening", E56, IFERROR( INDEX($E$2:$E$301, SMALL( IF( ($B$2:$B$301=B56) * ($C$2:$C$301=C56) * ($D$2:$D$301=D56) * ($F$2:$F$301=F56) * ($G$2:$G$301=G56) * ($H$2:$H$301=H56) * ($I$2:$I$301=I56) * ($J$2:$J$301=J56) * ($K$2:$K$301=K56) * ($E$2:$E$301<>"Evening"), ROW($E$2:$E$301)-ROW($E$2)+1, "" ), 1)), "Night" ) )} -> Night
A57: 2024-01-14 | B57: Pit A | C57: Seam 3 | D57: EX2500 | E57: Day | F57: 5415 | G57: 5800 | H57: 4.57 | I57: 0.38 | J57: 4.19 | K57: {=IF( ISNUMBER(DATEVALUE(A57)), TEXT(DATEVALUE(A57),"yyyy-mm-dd"), IFERROR( TEXT(INDEX($A$2:$A$301,MATCH(1, ($B$2:$B$301=B57) * ($C$2:$C$301=C57) * ($D$2:$D$301=D57) * ($E$2:$E$301=E57) * ($F$2:$F$301=F57) * ($G$2:$G$301=G57) * ($H$2:$H$301=H57) * ($I$2:$I$301=I57) * ($J$2:$J$301=J57),0)),"yyyy-mm-dd"), "Perlu Klarifikasi" ) )} -> 2024-01-14 | L57: {=IF( E57<>"Evening", E57, IFERROR( INDEX($E$2:$E$301, SMALL( IF( ($B$2:$B$301=B57) * ($C$2:$C$301=C57) * ($D$2:$D$301=D57) * ($F$2:$F$301=F57) * ($G$2:$G$301=G57) * ($H$2:$H$301=H57) * ($I$2:$I$301=I57) * ($J$2:$J$301=J57) * ($K$2:$K$301=K57) * ($E$2:$E$301<>"Evening"), ROW($E$2:$E$301)-ROW($E$2)+1, "" ), 1)), "Night" ) )} -> Day
A58: 2024-01-14 | B58: Pit A | C58: Seam 3 | D58: EX2500 | E58: Day | F58: 5415 | G58: 5800 | H58: 4.57 | I58: 0.38 | J58: 4.19 | K58: {=IF( ISNUMBER(DATEVALUE(A58)), TEXT(DATEVALUE(A58),"yyyy-mm-dd"), IFERROR( TEXT(INDEX($A$2:$A$301,MATCH(1, ($B$2:$B$301=B58) * ($C$2:$C$301=C58) * ($D$2:$D$301=D58) * ($E$2:$E$301=E58) * ($F$2:$F$301=F58) * ($G$2:$G$301=G58) * ($H$2:$H$301=H58) * ($I$2:$I$301=I58) * ($J$2:$J$301=J58),0)),"yyyy-mm-dd"), "Perlu Klarifikasi" ) )} -> 2024-01-14 | L58: {=IF( E58<>"Evening", E58, IFERROR( INDEX($E$2:$E$301, SMALL( IF( ($B$2:$B$301=B58) * ($C$2:$C$301=C58) * ($D$2:$D$301=D58) * ($F$2:$F$301=F58) * ($G$2:$G$301=G58) * ($H$2:$H$301=H58) * ($I$2:$I$301=I58) * ($J$2:$J$301=J58) * ($K$2:$K$301=K58) * ($E$2:$E$301<>"Evening"), ROW($E$2:$E$301)-ROW($E$2)+1, "" ), 1)), "Night" ) )} -> Day
A59: 2024-01-14 | B59: Pit A | C59: Seam 3 | D59: EX2500 | E59: Day | F59: 5415 | G59: 5800 | H59: 4.57 | I59: 0.38 | J59: 4.19 | K59: {=IF( ISNUMBER(DATEVALUE(A59)), TEXT(DATEVALUE(A59),"yyyy-mm-dd"), IFERROR( TEXT(INDEX($A$2:$A$301,MATCH(1, ($B$2:$B$301=B59) * ($C$2:$C$301=C59) * ($D$2:$D$301=D59) * ($E$2:$E$301=E59) * ($F$2:$F$301=F59) * ($G$2:$G$301=G59) * ($H$2:$H$301=H59) * ($I$2:$I$301=I59) * ($J$2:$J$301=J59),0)),"yyyy-mm-dd"), "Perlu Klarifikasi" ) )} -> 2024-01-14 | L59: {=IF( E59<>"Evening", E59, IFERROR( INDEX($E$2:$E$301, SMALL( IF( ($B$2:$B$301=B59) * ($C$2:$C$301=C59) * ($D$2:$D$301=D59) * ($F$2:$F$301=F59) * ($G$2:$G$301=G59) * ($H$2:$H$301=H59) * ($I$2:$I$301=I59) * ($J$2:$J$301=J59) * ($K$2:$K$301=K59) * ($E$2:$E$301<>"Evening"), ROW($E$2:$E$301)-ROW($E$2)+1, "" ), 1)), "Night" ) )} -> Day
A60: 2024-01-15 | B60: Pit A | C60: Seam 1 | D60: EX1100 | E60: Day | F60: 7864 | G60: 4876 | H60: 6.23 | I60: 1.01 | J60: 5.22 | K60: {=IF( ISNUMBER(DATEVALUE(A60)), TEXT(DATEVALUE(A60),"yyyy-mm-dd"), IFERROR( TEXT(INDEX($A$2:$A$301,MATCH(1, ($B$2:$B$301=B60) * ($C$2:$C$301=C60) * ($D$2:$D$301=D60) * ($E$2:$E$301=E60) * ($F$2:$F$301=F60) * ($G$2:$G$301=G60) * ($H$2:$H$301=H60) * ($I$2:$I$301=I60) * ($J$2:$J$301=J60),0)),"yyyy-mm-dd"), "Perlu Klarifikasi" ) )} -> 2024-01-15 | L60: {=IF( E60<>"Evening", E60, IFERROR( INDEX($E$2:$E$301, SMALL( IF( ($B$2:$B$301=B60) * ($C$2:$C$301=C60) * ($D$2:$D$301=D60) * ($F$2:$F$301=F60) * ($G$2:$G$301=G60) * ($H$2:$H$301=H60) * ($I$2:$I$301=I60) * ($J$2:$J$301=J60) * ($K$2:$K$301=K60) * ($E$2:$E$301<>"Evening"), ROW($E$2:$E$301)-ROW($E$2)+1, "" ), 1)), "Night" ) )} -> Day
...

Sheet Produksi_Unik
A1: Tanggal | B1: Pit | C1: Seam | D1: Excavator | E1: Shift | F1: OB_Volume | G1: Coal_Volume | H1: Working_Hours | I1: Delay_Hours | J1: Productive_Hours | K1: Normalisasi_Tanggal | L1: Validasi_Shift | M1: Delay_Cek | N1: Produktivitas_Excavator | O1: Estimated_Fuel | P1: Working_Hours_Cek | Q1: Rasio_Stripping
A2: 2024-01-01 | B2: Pit C | C2: Seam 1 | D2: EX1100 | E2: Evening | F2: 713 | G2: 6438 | H2: 9.92 | I2: 1.86 | J2: 8.06 | K2: 2024-01-01 | L2: Night | M2: =IF(ABS(H2-J2-I2) <= 0.01,"Valid","Invalid") -> Valid | N2: =G2/H2 -> 648.99194 | O2: =_xlfn.XLOOKUP(D2,'Fleet Master'!$A$2:$A$9,'Fleet Master'!$D$2:$D$9)*H2 -> 446.4 | P2: =IF(H2=I2+J2,"Valid","Invalid") -> Valid | Q2: =F2/G2 -> 0.11074868
A3: 2024-01-01 | B3: Pit C | C3: Seam 2 | D3: EX1100 | E3: Night | F3: 1366 | G3: 1078 | H3: 4.44 | I3: 0.72 | J3: 3.72 | K3: 2024-01-01 | L3: Night | M3: =IF(ABS(H3-J3-I3) <= 0.01,"Valid","Invalid") -> Valid | N3: =G3/H3 -> 242.79279 | O3: =_xlfn.XLOOKUP(D3,'Fleet Master'!$A$2:$A$9,'Fleet Master'!$D$2:$D$9)*H3 -> 199.8 | P3: =IF(H3=I3+J3,"Valid","Invalid") -> Valid | Q3: =F3/G3 -> 1.2671614
A4: 2024-01-02 | B4: Pit A | C4: Seam 1 | D4: EX2500 | E4: Day | F4: 2612 | G4: 2675 | H4: 7.16 | I4: 1.5 | J4: 5.66 | K4: 2024-01-02 | L4: Day | M4: =IF(ABS(H4-J4-I4) <= 0.01,"Valid","Invalid") -> Valid | N4: =G4/H4 -> 373.60335 | O4: =_xlfn.XLOOKUP(D4,'Fleet Master'!$A$2:$A$9,'Fleet Master'!$D$2:$D$9)*H4 -> 537 | P4: =IF(H4=I4+J4,"Valid","Invalid") -> Valid | Q4: =F4/G4 -> 0.9764486
A5: 2024-01-02 | B5: Pit B | C5: Seam 2 | D5: EX2500 | E5: Day | F5: 3737 | G5: 269 | H5: 9.95 | I5: 0.78 | J5: 9.17 | K5: 2024-01-02 | L5: Day | M5: =IF(ABS(H5-J5-I5) <= 0.01,"Valid","Invalid") -> Valid | N5: =G5/H5 -> 27.035176 | O5: =_xlfn.XLOOKUP(D5,'Fleet Master'!$A$2:$A$9,'Fleet Master'!$D$2:$D$9)*H5 -> 746.25 | P5: =IF(H5=I5+J5,"Valid","Invalid") -> Valid | Q5: =F5/G5 -> 13.892193
A6: 2024-01-02 | B6: Pit C | C6: Seam 2 | D6: EX2500 | E6: Day | F6: 7669 | G6: 4949 | H6: 7.54 | I6: 0.96 | J6: 6.58 | K6: 2024-01-02 | L6: Day | M6: =IF(ABS(H6-J6-I6) <= 0.01,"Valid","Invalid") -> Valid | N6: =G6/H6 -> 656.36605 | O6: =_xlfn.XLOOKUP(D6,'Fleet Master'!$A$2:$A$9,'Fleet Master'!$D$2:$D$9)*H6 -> 565.5 | P6: =IF(H6=I6+J6,"Valid","Invalid") -> Valid | Q6: =F6/G6 -> 1.549606
A7: 2024-01-03 | B7: Pit A | C7: Seam 1 | D7: EX1200 | E7: Night | F7: 684 | G7: 1349 | H7: 5.43 | I7: 0.27 | J7: 5.16 | K7: 2024-01-03 | L7: Night | M7: =IF(ABS(H7-J7-I7) <= 0.01,"Valid","Invalid") -> Valid | N7: =G7/H7 -> 248.43462 | O7: =_xlfn.XLOOKUP(D7,'Fleet Master'!$A$2:$A$9,'Fleet Master'!$D$2:$D$9)*H7 -> 260.64 | P7: =IF(H7=I7+J7,"Valid","Invalid") -> Valid | Q7: =F7/G7 -> 0.50704225
A8: 2024-01-03 | B8: Pit A | C8: Seam 2 | D8: EX1200 | E8: Day | F8: 8978 | G8: 3637 | H8: 4.71 | I8: 0.08 | J8: 4.63 | K8: 2024-01-03 | L8: Day | M8: =IF(ABS(H8-J8-I8) <= 0.01,"Valid","Invalid") -> Valid | N8: =G8/H8 -> 772.18684 | O8: =_xlfn.XLOOKUP(D8,'Fleet Master'!$A$2:$A$9,'Fleet Master'!$D$2:$D$9)*H8 -> 226.08 | P8: =IF(H8=I8+J8,"Valid","Invalid") -> Valid | Q8: =F8/G8 -> 2.468518
A9: 2024-01-03 | B9: Pit A | C9: Seam 1 | D9: EX1100 | E9: Evening | F9: 3336 | G9: 2526 | H9: 6.14 | I9: 0.63 | J9: 5.51 | K9: 2024-01-03 | L9: Day | M9: =IF(ABS(H9-J9-I9) <= 0.01,"Valid","Invalid") -> Valid | N9: =G9/H9 -> 411.40065 | O9: =_xlfn.XLOOKUP(D9,'Fleet Master'!$A$2:$A$9,'Fleet Master'!$D$2:$D$9)*H9 -> 276.3 | P9: =IF(H9=I9+J9,"Valid","Invalid") -> Valid | Q9: =F9/G9 -> 1.3206651
A10: 2024-01-03 | B10: Pit A | C10: Seam 2 | D10: EX1200 | E10: Night | F10: 2604 | G10: 1318 | H10: 6.25 | I10: 1.14 | J10: 5.11 | K10: 2024-01-03 | L10: Night | M10: =IF(ABS(H10-J10-I10) <= 0.01,"Valid","Invalid") -> Valid | N10: =G10/H10 -> 210.88 | O10: =_xlfn.XLOOKUP(D10,'Fleet Master'!$A$2:$A$9,'Fleet Master'!$D$2:$D$9)*H10 -> 300 | P10: =IF(H10=I10+J10,"Valid","Invalid") -> Valid | Q10: =F10/G10 -> 1.9757208
A11: 2024-01-03 | B11: Pit B | C11: Seam 2 | D11: EX2500 | E11: Night | F11: 3710 | G11: 3388 | H11: 8.73 | I11: 1.18 | J11: 7.55 | K11: 2024-01-03 | L11: Night | M11: =IF(ABS(H11-J11-I11) <= 0.01,"Valid","Invalid") -> Valid | N11: =G11/H11 -> 388.08706 | O11: =_xlfn.XLOOKUP(D11,'Fleet Master'!$A$2:$A$9,'Fleet Master'!$D$2:$D$9)*H11 -> 654.75 | P11: =IF(H11=I11+J11,"Valid","Invalid") -> Valid | Q11: =F11/G11 -> 1.0950413
A12: 2024-01-04 | B12: Pit C | C12: Seam 3 | D12: EX1200 | E12: Evening | F12: 5683 | G12: 5055 | H12: 4.59 | I12: 0.17 | J12: 4.42 | K12: 2024-01-04 | L12: Night | M12: =IF(ABS(H12-J12-I12) <= 0.01,"Valid","Invalid") -> Valid | N12: =G12/H12 -> 1101.3072 | O12: =_xlfn.XLOOKUP(D12,'Fleet Master'!$A$2:$A$9,'Fleet Master'!$D$2:$D$9)*H12 -> 220.32 | P12: =IF(H12=I12+J12,"Valid","Invalid") -> Valid | Q12: =F12/G12 -> 1.1242334
A13: 2024-01-05 | B13: Pit B | C13: Seam 1 | D13: EX2500 | E13: Night | F13: 4512 | G13: 1543 | H13: 5.16 | I13: 0.03 | J13: 5.13 | K13: 2024-01-05 | L13: Night | M13: =IF(ABS(H13-J13-I13) <= 0.01,"Valid","Invalid") -> Valid | N13: =G13/H13 -> 299.03101 | O13: =_xlfn.XLOOKUP(D13,'Fleet Master'!$A$2:$A$9,'Fleet Master'!$D$2:$D$9)*H13 -> 387 | P13: =IF(H13=I13+J13,"Valid","Invalid") -> Valid | Q13: =F13/G13 -> 2.9241737
... A77: 2024-02-16 | B77: Pit A | C77: Seam 1 | D77: EX2500 | E77: Night | F77: 5154 | G77: 2366 | H77: 5.06 | I77: 0.16 | J77: 4.9 | K77: 2024-02-16 | L77: Night | M77: =IF(ABS(H77-J77-I77) <= 0.01,"Valid","Invalid") -> Valid | N77: =G77/H77 -> 467.58893 | O77: =_xlfn.XLOOKUP(D77,'Fleet Master'!$A$2:$A$9,'Fleet Master'!$D$2:$D$9)*H77 -> 379.5 | P77: =IF(H77=I77+J77,"Valid","Invalid") -> Valid | Q77: =F77/G77 -> 2.1783601
B78: Pit A | C78: Seam 1 | D78: EX2500 | E78: Night | F78: 4956 | G78: 5518 | H78: 7.4 | I78: 0.09 | J78: 7.31 | K78: 2024-02-16 | L78: Night | M78: =IF(ABS(H78-J78-I78) <= 0.01,"Valid","Invalid") -> Valid | N78: =G78/H78 -> 745.67568 | O78: =_xlfn.XLOOKUP(D78,'Fleet Master'!$A$2:$A$9,'Fleet Master'!$D$2:$D$9)*H78 -> 555 | P78: =IF(H78=I78+J78,"Valid","Invalid") -> Valid | Q78: =F78/G78 -> 0.8981515
A79: 2024-02-17 | B79: Pit A | C79: Seam 3 | D79: EX1100 | E79: Night | F79: 7607 | G79: 4801 | H79: 6.5 | I79: 1.52 | J79: 4.98 | K79: 2024-02-17 | L79: Night | M79: =IF(ABS(H79-J79-I79) <= 0.01,"Valid","Invalid") -> Valid | N79: =G79/H79 -> 738.61538 | O79: =_xlfn.XLOOKUP(D79,'Fleet Master'!$A$2:$A$9,'Fleet Master'!$D$2:$D$9)*H79 -> 292.5 | P79: =IF(H79=I79+J79,"Valid","Invalid") -> Valid | Q79: =F79/G79 -> 1.5844616
